Workbook

Sheet Actividad
B2: Actividad: Selección de una muestra
B3: 1. Calcula el tamaño de muestra para la estimación del impuesto promedio de las MYPES mostradas en la MATRIZ de datos
C4: Considere un nivel de confianza del 92%, una varianza poblacional de 122500 y un margen de error de 100 soles
B5: 2. Calcula el tamaño de muestra para la estimación de la proporción de empresas que se encuentran de acuerdo con un nuevo rubro de impuesto
C6: Considere un nivel de confianza del 90%, P = 0.85 y un margen de error de 0.08
B7: 3. Extraer una muestra aleatoria simple de MYPES, para la estimación del impuesto promedio y la proporción de empresas que esán de acuerdo con el impuesto nuevo, teniendo en cuenta los tamaños de muestra encontrados en la pregunta 1. y en la pregunta 2.
B8: 4. Extraer una muestra aleatoria sistemática de MYPES, para la estimación del impuesto promedio y la proporción de empresas que esán de acuerdo con el impuesto nuevo, teniendo en cuenta los tamaños de muestra encontrados en la pregunta 1. y en la pregunta 2.
B11: Pregunta 1 | I11: Pregunta 2
B13: Tamaño de la muestra | E13: Variable: Impuesto | I13: Tamaño de la muestra | L13: Variable: Empresas que están de acuerdo con el nuevo impuesto
B15: Tamaño de la población | E15: N = | F15: =COUNTA(MATRIZ!A:A)-1 -> 1196 | I15: Tamaño de la población | L15: N = | M15: =COUNTA(MATRIZ!A:A)-1 -> 1196
B16: Nivel de confianza: | E16: 1 - α = | F16: 0.92 | H16: Z = | I16: =NORMSINV((1+F16)/2) -> 1.7506861 | J16: =INV.NORM.ESTAND(0.96) | L16: 1 - α = | M16: 0.9 | O16: Z = | P16: =NORMSINV((1+M16)/2) -> 1.6448536
B17: α = | E17: nivel de error | F17: =1-F16 -> 0.08 | I17: Margen de error: | L17: e = | M17: 0.08
B18: Margen de Error: | E18: e = | F18: 100 | I18: Proporción esperada | L18: P = | M18: 0.85
B19: Desviación estánd. Pob. | E19: σ = | F19: =SQRT(122500) -> 350 | I19: Complemento | L19: q = | M19: =1-M18 -> 0.15
B20: Tamaño de la muestra: | E20: n = | F20: =(F15*(I16^2)*(F19^2))/(((F15-1)*(F18^2))+((I16^2)*(F19^2))) -> 36.431833 | G20: =ROUNDUP(F20,0) -> 37 | I20: Tamaño de la muestra: | L20: n = | M20: =(M15*(P16^2)*M18*M19)/(((M15-1)*(M17^2))+((P16^2)*M18*M19)) -> 51.616483 | N20: =ROUNDUP(M20,0) -> 52
B22: n = (N·Z²·σ²) / ((N - 1)·e² + Z²·σ²) | I22: n = (N·Z²·p·q) / ((N - 1)·e² + Z²·p·q)
B25: Para las preguntas 3 y 4 se utiliza el mayor tamaño de muestra calculado. | N25: n = | O25: =MAX(G20,N20) -> 52

Sheet MATRIZ
A1: Id | B1: RAZÓN SOCIAL | C1: SECTOR
A2: 1 | B2: CONISLLA QUISPE EPIFANIO | C2: 2
A3: 2 | B3: MENDOZA MONTAÑEZ TEOBALDO CARLOS | C3: 2
A4: 3 | B4: CHAPOÑAN RODRIGUEZ JOSE LUIS | C4: 1
A5: 4 | B5: VILLA CRISOSTOMO IRMA VICTORIA | C5: 1 | E5: Sector | F5: Código
A6: 5 | B6: CAMPOS SALINAS DE LAM JESSICA JANET | C6: 1 | E6: Comercio | F6: 1
A7: 6 | B7: LT BABY STORE EIRL | C7: 1 | E7: Producción/Extracción | F7: 2
A8: 7 | B8: ATAUPILLCO OROS BRISSI MASSHIEL | C8: 6 | E8: Actividades Inmoviliarias | F8: 3
A9: 8 | B9: PAJUELO LIJARZA DONATO | C9: 1 | E9: Hoteles y restaurantes | F9: 4
A10: 9 | B10: ROCCO FILTRO EIRL | C10: 1 | E10: Transporte, almacenamiento y comunicación | F10: 5
A11: 10 | B11: CHOQUE QUISPE YANETH | C11: 4 | E11: Otras actividades de servicios | F11: 6
A12: 11 | B12: GIANKARS MOTORS EIRL | C12: 1
A13: 12 | B13: ICHUTA PALLE SAMUEL | C13: 1
A14: 13 | B14: DUBONP SA | C14: 1
A15: 14 | B15: MAYTA TITO MELITON | C15: 3
A16: 15 | B16: COMERCIAL GRAFICA JARA SRL | C16: 2
A17: 16 | B17: TENORIO MORENO NORA | C17: 4
A18: 17 | B18: ORTHOMEDIC EIRL | C18: 2
A19: 18 | B19: MAMANI VARGAS HUMBERTO | C19: 1
A20: 19 | B20: RANILLA FERNANDEZ ELIN LORENZO | C20: 3
A21: 20 | B21: HD IMPORTACIONES AREQUIPA EIRL | C21: 1
A22: 21 | B22: CUYOTUPAC VELIZ DEISSY HORTENSIA | C22: 1
A23: 22 | B23: INVERSIONES YAROSUBE MATEO EIRL | C23: 1
... A1197: 1196 | B1197: EVELDAY MAPECO SAC | C1197: 3

Sheet MAS
A1: Id | B1: RAZÓN SOCIAL | C1: SECTOR | D1: ALEATORIO | F1: Selección de muestra con muestreo aleatorio simple
A2: 587 | B2: CRUZ HUALLPA MARY LUZ | C2: 1 | D2: 3 | F2: Tamaño de la muestra | I2: Variable guía: Empresas que están de acuerdo con el nuevo impuesto
A3: 85 | B3: AMERICA LIFE EIRL | C3: 1 | D3: 5 | F3: Se utiliza el mayor tamaño calculado entre la pregunta 1 y la pregunta 2.
A4: 595 | B4: ORTEGA GARCIA ELBER | C4: 1 | D4: 6
A5: 957 | B5: KREA ILUSIONES LMA EIRL | C5: 2 | D5: 7 | F5: Tamaño de la población | I5: N = | J5: =Actividad!M15 -> 1196
A6: 292 | B6: HUAMAN BUSTINZA JULIO | C6: 2 | D6: 10 | F6: Nivel de confianza: | I6: 1 - α = | J6: =Actividad!M16 -> 0.9 | L6: Z = | M6: =Actividad!P16 -> 1.6448536
A7: 250 | B7: EMPRESA PROVEEDORA EL SOL SRL | C7: 1 | D7: 11 | F7: Margen de error: | I7: e = | J7: =Actividad!M17 -> 0.08
A8: 977 | B8: FLORES GARAY DILMER | C8: 1 | D8: 11 | F8: P = | I8: P = | J8: =Actividad!M18 -> 0.85
A9: 223 | B9: COMERCIO INTERNACIONAL NACIONAL Y SERVIC IOS SRL | C9: 1 | D9: 12 | F9: q = | I9: q = | J9: =Actividad!M19 -> 0.15
A10: 372 | B10: SERVICIOS INDUSTRIALES F & PJ YALO SAC | C10: 2 | D10: 16 | F10: Tamaño de la muestra: | I10: n = | J10: =Actividad!M20 -> 51.616483 | K10: =Actividad!N20 -> 52
A11: 121 | B11: CRUZ TITALO MAURO | C11: 1 | D11: 17
A12: 890 | B12: SIGNAAL INDUSTRIAL SAC | C12: 1 | D12: 23 | F12: Selección de la muestra
A13: 349 | B13: SKY 19 EIRL | C13: 2 | D13: 24 | F13: N° | G13: RAZÓN SOCIAL | H13: SECTOR | I13: ALEATORIO
A14: 557 | B14: CARDENAS DIAZ EFRAIN | C14: 1 | D14: 25 | F14: 1 | G14: =B2 -> CRUZ HUALLPA MARY LUZ | H14: =C2 -> 1 | I14: =D2 -> 3
A15: 636 | B15: EDITORIAL VALOR EIRL | C15: 2 | D15: 25 | F15: 2 | G15: =B3 -> AMERICA LIFE EIRL | H15: =C3 -> 1 | I15: =D3 -> 5
A16: 74 | B16: SERVICIOS MULTIPLES CORSA EIRL | C16: 3 | D16: 26 | F16: 3 | G16: =B4 -> ORTEGA GARCIA ELBER | H16: =C4 -> 1 | I16: =D4 -> 6
A17: 95 | B17: GUEVARA TORRES JESUS ELVIRA | C17: 2 | D17: 26 | F17: 4 | G17: =B5 -> KREA ILUSIONES LMA EIRL | H17: =C5 -> 2 | I17: =D5 -> 7
A18: 267 | B18: T & F INTERNATIONAL TRADING SRL | C18: 1 | D18: 28 | F18: 5 | G18: =B6 -> HUAMAN BUSTINZA JULIO | H18: =C6 -> 2 | I18: =D6 -> 10
A19: 221 | B19: GAMARRA MORALES HERNAN ERICK | C19: 5 | D19: 31 | F19: 6 | G19: =B7 -> EMPRESA PROVEEDORA EL SOL SRL | H19: =C7 -> 1 | I19: =D7 -> 11
A20: 722 | B20: CORP CAMACHO SAC | C20: 2 | D20: 33 | F20: 7 | G20: =B8 -> FLORES GARAY DILMER | H20: =C8 -> 1 | I20: =D8 -> 11
A21: 161 | B21: PINTO APAZA MARIA NORCA | C21: 1 | D21: 34 | F21: 8 | G21: =B9 -> COMERCIO INTERNACIONAL NACIONAL Y SERVIC IOS SRL | H21: =C9 -> 1 | I21: =D9 -> 12
A22: 248 | B22: B & W MASTER SERVICE SRL | C22: 1 | D22: 34 | F22: 9 | G22: =B10 -> SERVICIOS INDUSTRIALES F & PJ YALO SAC | H22: =C10 -> 2 | I22: =D10 -> 16
A23: 1012 | B23: CORPORACION CONTEX SAC | C23: 1 | D23: 38 | F23: 10 | G23: =B11 -> CRUZ TITALO MAURO | H23: =C11 -> 1 | I23: =D11 -> 17
A24: 1117 | B24: CORPORACION TIMALCO SAC | C24: 2 | D24: 41 | F24: 11 | G24: =B12 -> SIGNAAL INDUSTRIAL SAC | H24: =C12 -> 1 | I24: =D12 -> 23
A25: 195 | B25: CONFECCIONES WILSS EIRL | C25: 1 | D25: 43 | F25: 12 | G25: =B13 -> SKY 19 EIRL | H25: =C13 -> 2 | I25: =D13 -> 24
... A65: 946 | B65: JMC RACING SAC | C65: 1 | D65: 111 | F65: 52 | G65: =B53 -> JACINTO PERICHE OSCAR | H65: =C53 -> 1 | I65: =D53 -> 93
A66: 447 | B66: LLANQUE HUANCA EFRAIN | C66: 1 | D66: 113
A67: 611 | B67: CONSORCIO CURICH SAC | C67: 4 | D67: 116
A68: 1071 | B68: GUERRERO ROJAS SEGUNDO VICTOR | C68: 1 | D68: 116
A69: 970 | B69: HUAMAN GARCIA REYNALDO TEOFILO | C69: 5 | D69: 120
A70: 678 | B70: FACTORIA INDUSTRIAL ROBERTO ACEVEDO SAC | C70: 2 | D70: 121
A71: 869 | B71: AZUCARES PIURANOS EIRL | C71: 2 | D71: 125
A72: 207 | B72: ENRIQUEZ TRUJILLO ELIZABETH PILAR | C72: 1 | D72: 127
A73: 1075 | B73: INDUSTRIA CARDUCCI SAC | C73: 2 | D73: 127
A74: 98 | B74: ROBLEDO MONTERO CARLOS ENRIQUE | C74: 6 | D74: 128
A75: 734 | B75: RTC ELECTRIC SAC | C75: 2 | D75: 132
A76: 47 | B76: CORPORACION ALBANTEX SAC | C76: 1 | D76: 142
A77: 209 | B77: HUAMAN QUISPE JESUS ANTONIO | C77: 2 | D77: 144
... A1197: 809 | B1197: NEGOCIOS KAVEL EIRL | C1197: 1 | D1197: 1999

Sheet MS
A1: Id | B1: RAZÓN SOCIAL | C1: SECTOR | E1: Selección de muestra con muestreo sistemático
A2: 1 | B2: CONISLLA QUISPE EPIFANIO | C2: 2 | E2: Tamaño de la muestra | H2: Variable guía: Empresas que están de acuerdo con el nuevo impuesto
A3: 2 | B3: MENDOZA MONTAÑEZ TEOBALDO CARLOS | C3: 2
A4: 3 | B4: CHAPOÑAN RODRIGUEZ JOSE LUIS | C4: 1 | E4: Tamaño de la población | H4: N = | I4: =Actividad!M15 -> 1196
A5: 4 | B5: VILLA CRISOSTOMO IRMA VICTORIA | C5: 1 | E5: Nivel de confianza: | H5: 1 - α = | I5: =Actividad!M16 -> 0.9 | J5: Z = | K5: =Actividad!P16 -> 1.6448536
A6: 5 | B6: CAMPOS SALINAS DE LAM JESSICA JANET | C6: 1 | E6: Margen de error: | H6: e = | I6: =Actividad!M17 -> 0.08
A7: 6 | B7: LT BABY STORE EIRL | C7: 1 | E7: P = | H7: P = | I7: =Actividad!M18 -> 0.85
A8: 7 | B8: ATAUPILLCO OROS BRISSI MASSHIEL | C8: 6 | E8: q = | H8: q = | I8: =Actividad!M19 -> 0.15
A9: 8 | B9: PAJUELO LIJARZA DONATO | C9: 1 | E9: Tamaño de la muestra: | H9: n = | I9: =Actividad!M20 -> 51.616483 | J9: =Actividad!N20 -> 52
A10: 9 | B10: ROCCO FILTRO EIRL | C10: 1
A11: 10 | B11: CHOQUE QUISPE YANETH | C11: 4 | E11: Selección de la muestra
A12: 11 | B12: GIANKARS MOTORS EIRL | C12: 1 | E12: Intervalo de selección | H12: k = | I12: =ROUND(I4/J9,0) -> 23
A13: 12 | B13: ICHUTA PALLE SAMUEL | C13: 1 | E13: Arranque aleatorio | H13: r = | I13: 17
A14: 13 | B14: DUBONP SA | C14: 1
A15: 14 | B15: MAYTA TITO MELITON | C15: 3 | E15: N° | F15: Id | G15: RAZÓN SOCIAL | H15: SECTOR
A16: 15 | B16: COMERCIAL GRAFICA JARA SRL | C16: 2 | E16: 1 | F16: =$I$13 -> 17 | G16: =INDEX(MATRIZ!B:B,F16+1) -> ORTHOMEDIC EIRL | H16: =INDEX(MATRIZ!C:C,F16+1) -> 2
A17: 16 | B17: TENORIO MORENO NORA | C17: 4 | E17: 2 | F17: =F16+$I$12 -> 40 | G17: =INDEX(MATRIZ!B:B,F17+1) -> M & A INSTALACIONES PROFESIONALES SAC | H17: =INDEX(MATRIZ!C:C,F17+1) -> 3
A18: 17 | B18: ORTHOMEDIC EIRL | C18: 2 | E18: 3 | F18: =F17+$I$12 -> 63 | G18: =INDEX(MATRIZ!B:B,F18+1) -> CONDORI CHURA PASTORA | H18: =INDEX(MATRIZ!C:C,F18+1) -> 1
A19: 18 | B19: MAMANI VARGAS HUMBERTO | C19: 1 | E19: 4 | F19: =F18+$I$12 -> 86 | G19: =INDEX(MATRIZ!B:B,F19+1) -> BUENDIA POMA RODRIGO NICOLAS | H19: =INDEX(MATRIZ!C:C,F19+1) -> 2
A20: 19 | B20: RANILLA FERNANDEZ ELIN LORENZO | C20: 3 | E20: 5 | F20: =F19+$I$12 -> 109 | G20: =INDEX(MATRIZ!B:B,F20+1) -> QUINTANA PINEDO MARIA MANUELA | H20: =INDEX(MATRIZ!C:C,F20+1) -> 1
A21: 20 | B21: HD IMPORTACIONES AREQUIPA EIRL | C21: 1 | E21: 6 | F21: =F20+$I$12 -> 132 | G21: =INDEX(MATRIZ!B:B,F21+1) -> MULTINEGOCIOS INFORMATICOS SAC | H21: =INDEX(MATRIZ!C:C,F21+1) -> 1
A22: 21 | B22: CUYOTUPAC VELIZ DEISSY HORTENSIA | C22: 1 | E22: 7 | F22: =F21+$I$12 -> 155 | G22: =INDEX(MATRIZ!B:B,F22+1) -> APAZA APAZA REINALDO | H22: =INDEX(MATRIZ!C:C,F22+1) -> 1
A23: 22 | B23: INVERSIONES YAROSUBE MATEO EIRL | C23: 1 | E23: 8 | F23: =F22+$I$12 -> 178 | G23: =INDEX(MATRIZ!B:B,F23+1) -> DAVILA SINACAY ROSITA ANGELICA | H23: =INDEX(MATRIZ!C:C,F23+1) -> 1
A24: 23 | B24: ALINORTE SAC | C24: 1 | E24: 9 | F24: =F23+$I$12 -> 201 | G24: =INDEX(MATRIZ!B:B,F24+1) -> ALMEN ESTABLECIMIENTOS EIRL | H24: =INDEX(MATRIZ!C:C,F24+1) -> 1
A25: 24 | B25: EMPRESA GUO SAC | C25: 4 | E25: 10 | F25: =F24+$I$12 -> 224 | G25: =INDEX(MATRIZ!B:B,F25+1) -> ACHO YAPUCHURA MARISOL | H25: =INDEX(MATRIZ!C:C,F25+1) -> 1
A26: 25 | B26: OMMIANAVAL EIRL | C26: 6 | E26: 11 | F26: =F25+$I$12 -> 247 | G26: =INDEX(MATRIZ!B:B,F26+1) -> JOMM S CORP EIRL | H26: =INDEX(MATRIZ!C:C,F26+1) -> 1
A27: 26 | B27: ASOCIADOS GADIEL SRL | C27: 1 | E27: 12 | F27: =F26+$I$12 -> 270 | G27: =INDEX(MATRIZ!B:B,F27+1) -> TENORIO AREVALO ARTURO | H27: =INDEX(MATRIZ!C:C,F27+1) -> 3
A28: 27 | B28: PRO & FAMM EIRL | C28: 2 | E28: 13 | F28: =F27+$I$12 -> 293 | G28: =INDEX(MATRIZ!B:B,F28+1) -> COPIADORAS IMPORT EIRL | H28: =INDEX(MATRIZ!C:C,F28+1) -> 3
... A67: 66 | B67: ALCANTARA SILVA JORDY WILLIAM | C67: 1 | E67: 52 | F67: =F66+$I$12 -> 1190 | G67: =INDEX(MATRIZ!B:B,F67+1) -> QUIO USCAMAYTA CESAR FELIPE | H67: =INDEX(MATRIZ!C:C,F67+1) -> 1
A68: 67 | B68: PINILLOS ENCISO OLGA | C68: 1
A69: 68 | B69: TEXTILE CLOTHING SOLUTION SAC | C69: 2
A70: 69 | B70: MEIND & GYM SAC | C70: 2
A71: 70 | B71: VILCA LUNA CHARMILY UBALDINA | C71: 1
A72: 71 | B72: COAQUIRA PACORI RUFINO | C72: 5
A73: 72 | B73: 2001 CAR SERVICE EIRL | C73: 1
A74: 73 | B74: HUANCA CONDORI LUCIO | C74: 5
A75: 74 | B75: SERVICIOS MULTIPLES CORSA EIRL | C75: 3
A76: 75 | B76: PAREDES VARGAS CRISOSTOMO | C76: 1
A77: 76 | B77: SODI & C F IMPORT - EXPORT EIRL | C77: 1
A78: 77 | B78: MARRUFO EL CONSTRUCTOR EIRL | C78: 1
...
